<?xml version="1.0" ?>
<robot name="gen3" xmlns:xacro="http://ros.org/wiki/xacro">
	<!-- Ground & platform -->
	<link name="floor_link">
		<inertial>
			<mass value="0.01"/>
			<inertia ixx="0.001" iyy="0.001" izz="0.001" ixy="0" ixz="0" iyz="0"/>
		</inertial>
		<collision name="floor">
			<origin xyz="0 -1. 0"/>
			<geometry>
				<box size="10 2. 10"/>
			</geometry>
		</collision>
	</link>
	<link name="platform_link">
		<inertial>
			<mass value="0.01"/>
			<inertia ixx="0.001" iyy="0.001" izz="0.001" ixy="0" ixz="0" iyz="0"/>
		</inertial>
		<visual name="platform">
			<origin xyz="0 0 0.26" rpy="0 0 0" />
			<geometry>
				<mesh filename="meshes/visual/swan_main_v1.3.stl"/>
			</geometry>
		</visual>
		<collision name="platform_wheels">
			<origin xyz="0 0.1 0.035" />
			<geometry>
				<box size="0.64 0.2 0.622" />
			</geometry>
		</collision>
		<collision name="platform_base">
			<origin xyz="0 0.24844 0.033504" rpy="0.47472955 0 0" />
			<geometry>
				<box size="0.62 0.2 0.6" />
			</geometry>
		</collision>
		<collision name="platform_top">
			<origin xyz="0 0.829664 -0.140145" />
			<geometry>
				<box size="0.68 1.34 0.2717" />
			</geometry>
		</collision>
	</link>
	<joint name="floor_joint" type="fixed">
		<parent link="floor_link"/>
		<child link="platform_link"/>
	</joint>

	<!-- Robotic arm -->
	<link name="base_link">
		<inertial>
			<origin rpy="0 0 0" xyz="-0.000648 -0.000166 0.084487"/>
			<mass value="1.697"/>
			<inertia ixx="0.004622" ixy="9E-06" ixz="6E-05" iyy="0.004495" iyz="9E-06" izz="0.002079"/>
		</inertial>
		<visual>
			<origin rpy="0 0 0" xyz="0 0 0"/>
			<geometry>
				<mesh filename="meshes/visual/base_link.stl"/>
			</geometry>
			<material name="">
				<color rgba="0.75294 0.75294 0.75294 1"/>
			</material>
		</visual>
		<collision name="base_link.STL">
			<origin rpy="0 0.0330555506034 0" xyz="-0.0023908666223 0 0.0798607867659"/>
			<geometry>
				<cylinder radius="0.0526472043059" length="0.1310530455"/>
			</geometry>
		</collision>
		<collision_checking><capsule name="base_link.STL"/></collision_checking>
	</link>
	<joint name="platform_joint" type="fixed">
		<origin rpy="0 0 0" xyz="0 1 0"/>
		<parent link="platform_link"/>
		<child link="base_link"/>
	</joint>
	<link name="shoulder_link">
		<inertial>
			<origin rpy="0 0 0" xyz="0 -0.010364 -0.07336"/>
			<mass value="1.3773"/>
			<inertia ixx="0.00457" ixy="1E-06" ixz="2E-06" iyy="0.004831" iyz="0.000448" izz="0.001409"/>
		</inertial>
		<visual>
			<origin rpy="0 0 0" xyz="0 0 0"/>
			<geometry>
				<mesh filename="meshes/visual/shoulder_link.stl"/>
			</geometry>
			<material name="">
				<color rgba="0.75294 0.75294 0.75294 1"/>
			</material>
		</visual>
		<collision name="shoulder_link.STL">
			<origin rpy="3.06288974602 0.00117120165879 0.0297450477115" xyz="0 -0.00398850493957 -0.0803051787635"/>
			<geometry>
				<cylinder radius="0.0533960543631" length="0.0966431295067"/>
			</geometry>
		</collision>
		<collision_checking><capsule name="shoulder_link.STL"/></collision_checking>
	</link>
	<joint name="joint_1" type="revolute">
		<origin rpy="3.1416 0 0" xyz="0 0 0.15643"/>
		<parent link="base_link"/>
		<child link="shoulder_link"/>
		<axis xyz="0 0 1"/>
		<!-- Large actuator ; max velocity: 79.64°/s (1.39rad/s) [Kinova/Table 39] ; max torque: 39 Nm [Kinova/Table 43] -->
		<limit lower="-15.141592653589793" upper="15.141592653589793" effort="39.0" velocity="1.39"/>
		<!-- <limit lower="-3.141592653589793" upper="3.141592653589793" effort="39.0" velocity="1.39"/> -->
	</joint>
	<link name="half_arm_1_link">
		<inertial>
			<origin rpy="0 0 0" xyz="0 -0.09958 -0.013278"/>
			<mass value="1.1636"/>
			<inertia ixx="0.011088" ixy="5E-06" ixz="0" iyy="0.001072" iyz="-0.000691" izz="0.011255"/>
		</inertial>
		<visual>
			<origin rpy="0 0 0" xyz="0 0 0"/>
			<geometry>
				<mesh filename="meshes/visual/half_arm_1_link.stl"/>
			</geometry>
			<material name="">
				<color rgba="0.75294 0.75294 0.75294 1"/>
			</material>
		</visual>
		<collision name="half_arm_1_link.STL">
			<origin rpy="1.51034107213 0.000341280404462 0.000321247651899" xyz="0 -0.104776395777 -0.0127937104817"/>
			<geometry>
				<cylinder radius="0.0474858593686" length="0.217281245077"/>
			</geometry>
		</collision>
		<collision_checking><capsule name="half_arm_1_link.STL"/></collision_checking>
	</link>
	<joint name="joint_2" type="revolute">
		<origin rpy="1.5708 0 0" xyz="0 0.005375 -0.12838"/>
		<parent link="shoulder_link"/>
		<child link="half_arm_1_link"/>
		<axis xyz="0 0 1"/>
		<!-- Large actuator ; max velocity: 79.64°/s (1.39rad/s) [Kinova/Table 39] ; max torque: 39 Nm [Kinova/Table 43] -->
		<limit effort="39.0" lower="-2.36" upper="2.36" velocity="1.39"/>
	</joint>
	<link name="half_arm_2_link">
		<inertial>
			<origin rpy="0 0 0" xyz="0 -0.006641 -0.117892"/>
			<mass value="1.1636"/>
			<inertia ixx="0.010932" ixy="0" ixz="-7E-06" iyy="0.011127" iyz="0.000606" izz="0.001043"/>
		</inertial>
		<visual>
			<origin rpy="0 0 0" xyz="0 0 0"/>
			<geometry>
				<mesh filename="meshes/visual/half_arm_2_link.stl"/>
			</geometry>
			<material name="">
				<color rgba="0.75294 0.75294 0.75294 1"/>
			</material>
		</visual>
		<collision name="half_arm_2_link.STL">
			<origin rpy="-0.0220457234566 0 0" xyz="0 -0.00223715710252 -0.122470355579"/>
			<geometry>
				<cylinder radius="0.0518790954755" length="0.186066168303"/>
			</geometry>
		</collision>
		<collision_checking><capsule name="half_arm_2_link.STL"/></collision_checking>
	</link>
	<joint name="joint_3" type="revolute">
		<origin rpy="-1.5708 0 0" xyz="0 -0.21038 -0.006375"/>
		<parent link="half_arm_1_link"/>
		<child link="half_arm_2_link"/>
		<axis xyz="0 0 1"/>
		<!-- Large actuator ; max velocity: 79.64°/s (1.39rad/s) [Kinova/Table 39] ; max torque: 39 Nm [Kinova/Table 43] -->
		<limit lower="-15.141592653589793" upper="15.141592653589793" effort="39.0" velocity="1.39"/>
		<!-- <limit lower="-3.141592653589793" upper="3.141592653589793" effort="39.0" velocity="1.39"/> -->
	</joint>
	<link name="forearm_link">
		<inertial>
			<origin rpy="0 0 0" xyz="0 -0.075478 -0.015006"/>
			<mass value="0.9302"/>
			<inertia ixx="0.008147" ixy="-1E-06" ixz="0" iyy="0.000631" iyz="-0.0005" izz="0.008316"/>
		</inertial>
		<visual>
			<origin rpy="0 0 0" xyz="0 0 0"/>
			<geometry>
				<mesh filename="meshes/visual/forearm_link.stl"/>
			</geometry>
			<material name="">
				<color rgba="0.75294 0.75294 0.75294 1"/>
			</material>
		</visual>
		<collision name="forearm_link.STL">
			<origin rpy="1.49917556512 0 0" xyz="0 -0.0921487074838 -0.0132842620784"/>
			<geometry>
				<cylinder radius="0.0473766827239" length="0.193095847062"/>
			</geometry>
		</collision>
		<collision_checking><capsule name="forearm_link.STL"/></collision_checking>
	</link>
	<joint name="joint_4" type="revolute">
		<origin rpy="1.5708 0 0" xyz="0 0.006375 -0.21038"/>
		<parent link="half_arm_2_link"/>
		<child link="forearm_link"/>
		<axis xyz="0 0 1"/>
		<!-- Large actuator ; max velocity: 79.64°/s (1.39rad/s) [Kinova/Table 39] ; max torque: 39 Nm [Kinova/Table 43] -->
		<limit effort="39.0" lower="-2.55" upper="2.55" velocity="1.39"/>
	</joint>
	<link name="spherical_wrist_1_link">
		<inertial>
			<origin rpy="0 0 0" xyz="0 -0.009432 -0.063883"/>
			<mass value="0.6781"/>
			<inertia ixx="0.001596" ixy="0" ixz="0" iyy="0.001607" iyz="0.000256" izz="0.000399"/>
		</inertial>
		<visual>
			<origin rpy="0 0 0" xyz="0 0 0"/>
			<geometry>
				<mesh filename="meshes/visual/spherical_wrist_1_link.stl"/>
			</geometry>
			<material name="">
				<color rgba="0.75294 0.75294 0.75294 1"/>
			</material>
		</visual>
		<collision name="spherical_wrist_1_link.STL">
			<origin rpy="-0.144635993459 -0.00982965058857 0.000712108182365" xyz="-0.000324509981414 -0.00704006754193 -0.0667845503492"/>
			<geometry>
				<cylinder radius="0.0429609807107" length="0.078927849255"/>
			</geometry>
		</collision>
		<collision_checking><capsule name="spherical_wrist_1_link.STL"/></collision_checking>
	</link>
	<joint name="joint_5" type="revolute">
		<origin rpy="-1.5708 0 0" xyz="0 -0.20843 -0.006375"/>
		<parent link="forearm_link"/>
		<child link="spherical_wrist_1_link"/>
		<axis xyz="0 0 1"/>
		<!-- Small actuator ; max velocity: 69.91°/s (1.22rad/s) [Kinova/Table 39] ; max torque: 9.0Nm [Kinova/Table 43] -->
		<limit lower="-15.141592653589793" upper="15.141592653589793" effort="9.0" velocity="1.22"/>
		<!-- <limit lower="-3.141592653589793" upper="3.141592653589793" effort="9.0" velocity="1.22"/> -->
	</joint>
	<link name="spherical_wrist_2_link">
		<inertial>
			<origin rpy="0 0 0" xyz="0 -0.045483 -0.00965"/>
			<mass value="0.6781"/>
			<inertia ixx="0.001641" ixy="0" ixz="0" iyy="0.00041" iyz="-0.000278" izz="0.001641"/>
		</inertial>
		<visual>
			<origin rpy="0 0 0" xyz="0 0 0"/>
			<geometry>
				<mesh filename="meshes/visual/spherical_wrist_2_link.stl"/>
			</geometry>
			<material name="">
				<color rgba="0.75294 0.75294 0.75294 1"/>
			</material>
		</visual>
		<collision name="spherical_wrist_2_link.STL">
			<origin rpy="1.36951994318 0.00233911005591 0.00191003459557" xyz="0 -0.0513828829317 -0.00998136538748"/>
			<geometry>
				<cylinder radius="0.039021043289" length="0.102460004368"/>
			</geometry>
		</collision>
		<collision_checking><capsule name="spherical_wrist_2_link.STL"/></collision_checking>
	</link>
	<joint name="joint_6" type="revolute">
		<origin rpy="1.5708 0 0" xyz="0 0.00017505 -0.10593"/>
		<parent link="spherical_wrist_1_link"/>
		<child link="spherical_wrist_2_link"/>
		<axis xyz="0 0 1"/>
		<!-- Small actuator ; max velocity: 69.91°/s (1.22rad/s) [Kinova/Table 39] ; max torque: 9.0Nm [Kinova/Table 43] -->
		<limit effort="9.0" lower="-2.20" upper="2.20" velocity="1.22"/>
	</joint>
	<link name="bracelet_link">
		<inertial>
			<origin rpy="0 0 0" xyz="-0.000281 -0.011402 -0.029798"/>
			<mass value="0.5006"/>
			<inertia ixx="0.000587" ixy="3E-06" ixz="3E-06" iyy="0.000369" iyz="0.000118" izz="0.000609"/>
		</inertial>
		<visual>
			<origin rpy="0 0 0" xyz="0 0 0"/>
			<geometry>
				<mesh filename="meshes/visual/bracelet_link.stl"/>
			</geometry>
			<material name="">
				<color rgba="0.75294 0.75294 0.75294 1"/>
			</material>
		</visual>
		<collision name="bracelet_link.STL">
			<origin rpy="-1.02104482021 0.659439004585 -0.378715199091" xyz="0.00121351109823 -0.0240686106511 -0.0379829008005"/>
			<geometry>
				<cylinder radius="0.0665770855028" length="0.00249856761032"/>
			</geometry>
		</collision>
		<collision_checking><capsule name="bracelet_link.STL"/></collision_checking>
	</link>
	<joint name="joint_7" type="revolute">
		<origin rpy="-1.5708 0 0" xyz="0 -0.10593 -0.00017505"/>
		<parent link="spherical_wrist_2_link"/>
		<child link="bracelet_link"/>
		<axis xyz="0 0 1"/>
		<!-- Small actuator ; max velocity: 69.91°/s (1.22rad/s) [Kinova/Table 39] ; max torque: 9.0Nm [Kinova/Table 43] -->
		<limit lower="-15.141592653589793" upper="15.141592653589793" effort="9.0" velocity="1.22"/>
		<!-- <limit lower="-3.141592653589793" upper="3.141592653589793" effort="9.0" velocity="1.22"/> -->
	</joint>
	<link name="end_effector_link">
		<inertial>
			<mass value="0.001"/>
			<inertia ixx="0.0001" ixy="0" ixz="0" iyy="0.0001" iyz="0" izz="0.0001"/>
		</inertial>
		<visual>
			<origin rpy="-1.5708 1.5708 0" xyz="0 0 0"/>
			<geometry>
				<mesh filename="meshes/visual/main_effector_simplified.stl"/>
			</geometry>
		</visual>
		<collision name="effector_v2_volume.STL">
			<!--origin rpy="1.60196664631 0 0" xyz="1.73867028473e-05 0.113682273327 0.00398902243811"/-->
			<origin rpy="1.5708 0 0" xyz="0 0.123682273327 0"/>
			<geometry>
				<cylinder radius="0.045" length="0.48"/>
			</geometry>
		</collision>
		<collision name="effector_v2_volume.STL_2">
			<origin rpy="0 1.5708 0" xyz="0.015 0.29 0"/>
			<geometry>
				<cylinder radius="0.065" length="0.10"/>
			</geometry>
		</collision>
		<collision_checking><capsule name="effector_v2_volume.STL"/></collision_checking>
	</link>
	<joint name="end_effector" type="fixed">
		<origin xyz="0 0 -0.0615250000000001" rpy="-1.5708 0 0"/>
		<parent link="bracelet_link"/>
		<child link="end_effector_link"/>
	</joint>
	<link name="camera_link"/>
	<joint name="camera_joint" type="fixed">
		<origin
			rpy="3.1416 -1.5708 0"
			xyz="0.057 0.29 0"/>
		<parent link="end_effector_link"/>
		<child link="camera_link"/>
	</joint>
</robot>
